[2024-07-08T21:54:42.720+0000] {local_task_job_runner.py:120} INFO - ::group::Pre task execution logs
[2024-07-08T21:54:42.818+0000] {taskinstance.py:2076} INFO - Dependencies all met for dep_context=non-requeueable deps ti=<TaskInstance: etl.create_tables manual__2024-07-08T21:54:37.612597+00:00 [queued]>
[2024-07-08T21:54:42.827+0000] {taskinstance.py:2076} INFO - Dependencies all met for dep_context=requeueable deps ti=<TaskInstance: etl.create_tables manual__2024-07-08T21:54:37.612597+00:00 [queued]>
[2024-07-08T21:54:42.827+0000] {taskinstance.py:2306} INFO - Starting attempt 1 of 1
[2024-07-08T21:54:42.849+0000] {taskinstance.py:2330} INFO - Executing <Task(PythonOperator): create_tables> on 2024-07-08 21:54:37.612597+00:00
[2024-07-08T21:54:42.868+0000] {standard_task_runner.py:90} INFO - Running: ['***', 'tasks', 'run', 'etl', 'create_tables', 'manual__2024-07-08T21:54:37.612597+00:00', '--job-id', '4', '--raw', '--subdir', 'DAGS_FOLDER/etl.py', '--cfg-path', '/tmp/tmprhyq78zh']
[2024-07-08T21:54:42.871+0000] {logging_mixin.py:188} WARNING - /home/***/.local/lib/python3.12/site-packages/***/task/task_runner/standard_task_runner.py:61 DeprecationWarning: This process (pid=13777) is multi-threaded, use of fork() may lead to deadlocks in the child.
[2024-07-08T21:54:42.872+0000] {standard_task_runner.py:63} INFO - Started process 13799 to run task
[2024-07-08T21:54:42.873+0000] {standard_task_runner.py:91} INFO - Job 4: Subtask create_tables
[2024-07-08T21:54:42.932+0000] {task_command.py:426} INFO - Running <TaskInstance: etl.create_tables manual__2024-07-08T21:54:37.612597+00:00 [running]> on host 8c15d98f81a6
[2024-07-08T21:54:43.050+0000] {taskinstance.py:2648} INFO - Exporting env vars: AIRFLOW_CTX_DAG_OWNER='***' AIRFLOW_CTX_DAG_ID='etl' AIRFLOW_CTX_TASK_ID='create_tables' AIRFLOW_CTX_EXECUTION_DATE='2024-07-08T21:54:37.612597+00:00' AIRFLOW_CTX_TRY_NUMBER='1' AIRFLOW_CTX_DAG_RUN_ID='manual__2024-07-08T21:54:37.612597+00:00'
[2024-07-08T21:54:43.052+0000] {taskinstance.py:430} INFO - ::endgroup::
[2024-07-08T21:54:43.075+0000] {taskinstance.py:441} INFO - ::group::Post task execution logs
[2024-07-08T21:54:43.095+0000] {taskinstance.py:2905} ERROR - Task failed with exception
Traceback (most recent call last):
  File "/home/airflow/.local/lib/python3.12/site-packages/airflow/models/taskinstance.py", line 465, in _execute_task
    result = _execute_callable(context=context, **execute_callable_kwargs)
             ^^^^^^^^^^^^^^^^^^^^^^^^^^^^^^^^^^^^^^^^^^^^^^^^^^^^^^^^^^^^^
  File "/home/airflow/.local/lib/python3.12/site-packages/airflow/models/taskinstance.py", line 432, in _execute_callable
    return execute_callable(context=context, **execute_callable_kwargs)
           ^^^^^^^^^^^^^^^^^^^^^^^^^^^^^^^^^^^^^^^^^^^^^^^^^^^^^^^^^^^^
  File "/home/airflow/.local/lib/python3.12/site-packages/airflow/models/baseoperator.py", line 401, in wrapper
    return func(self, *args, **kwargs)
           ^^^^^^^^^^^^^^^^^^^^^^^^^^^
  File "/home/airflow/.local/lib/python3.12/site-packages/airflow/operators/python.py", line 235, in execute
    return_value = self.execute_callable()
                   ^^^^^^^^^^^^^^^^^^^^^^^
  File "/home/airflow/.local/lib/python3.12/site-packages/airflow/operators/python.py", line 252, in execute_callable
    return self.python_callable(*self.op_args, **self.op_kwargs)
           ^^^^^^^^^^^^^^^^^^^^^^^^^^^^^^^^^^^^^^^^^^^^^^^^^^^^^
  File "/opt/airflow/dags/etl.py", line 31, in _create_tables
    conn = hook.get_conn()
           ^^^^^^^^^^^^^^^
  File "/home/airflow/.local/lib/python3.12/site-packages/airflow/providers/postgres/hooks/postgres.py", line 145, in get_conn
    conn = deepcopy(self.connection or self.get_connection(conn_id))
                                       ^^^^^^^^^^^^^^^^^^^^^^^^^^^^
  File "/home/airflow/.local/lib/python3.12/site-packages/airflow/hooks/base.py", line 83, in get_connection
    conn = Connection.get_connection_from_secrets(conn_id)
           ^^^^^^^^^^^^^^^^^^^^^^^^^^^^^^^^^^^^^^^^^^^^^^^
  File "/home/airflow/.local/lib/python3.12/site-packages/airflow/models/connection.py", line 519, in get_connection_from_secrets
    raise AirflowNotFoundException(f"The conn_id `{conn_id}` isn't defined")
airflow.exceptions.AirflowNotFoundException: The conn_id `my_postgres` isn't defined
[2024-07-08T21:54:43.104+0000] {taskinstance.py:1206} INFO - Marking task as FAILED. dag_id=etl, task_id=create_tables, run_id=manual__2024-07-08T21:54:37.612597+00:00, execution_date=20240708T215437, start_date=20240708T215442, end_date=20240708T215443
[2024-07-08T21:54:43.133+0000] {standard_task_runner.py:110} ERROR - Failed to execute job 4 for task create_tables (The conn_id `my_postgres` isn't defined; 13799)
[2024-07-08T21:54:43.173+0000] {local_task_job_runner.py:240} INFO - Task exited with return code 1
[2024-07-08T21:54:43.200+0000] {taskinstance.py:3503} INFO - 0 downstream tasks scheduled from follow-on schedule check
[2024-07-08T21:54:43.214+0000] {local_task_job_runner.py:222} INFO - ::endgroup::
